<?xml version="1.0" encoding="utf-8"?>
<!-- This URDF was automatically created by SolidWorks to URDF Exporter! Originally created by Stephen Brawner (brawner@gmail.com) 
     Commit Version: 1.6.0-4-g7f85cfe  Build Version: 1.6.7995.38578
     For more information, please see http://wiki.ros.org/sw_urdf_exporter -->
<robot
  name="Assem1.SLDASM">
  <link
    name="base_link">
    <inertial>
      <origin
        xyz="0.17083 0.20648 -0.11785"
        rpy="0 0 0" />
      <mass
        value="0.15" />
      <inertia
        ixx="0.00052037"
        ixy="1.3913E-07"
        ixz="-1.1765E-06"
        iyy="0.00068873"
        iyz="1.9594E-07"
        izz="0.00018815" />
    </inertial>
    <visual>
      <origin
        xyz="0 0 0"
        rpy="0 0 0" />
      <geometry>
        <mesh
          filename="C:\\Users\\antoz\\Crawler\\Assem1.SLDASM\\meshes\\base_link.STL" />
      </geometry>
      <material
        name="">
        <color
          rgba="0.79216 0.81961 0.93333 1" />
      </material>
    </visual>
    <collision>
      <origin
        xyz="0 0 0"
        rpy="0 0 0" />
      <geometry>
        <mesh
          filename="package://Assem1.SLDASM/meshes/base_link.STL" />
      </geometry>
    </collision>
  </link>
  <link
    name="Right Wheel">
    <inertial>
      <origin
        xyz="0.0096363 -1.4572E-16 2.498E-16"
        rpy="0 0 0" />
      <mass
        value="0.05" />
      <inertia
        ixx="2.1887E-05"
        ixy="-5.6453E-21"
        ixz="-1.5631E-21"
        iyy="1.1643E-05"
        iyz="4.2352E-22"
        izz="1.1643E-05" />
    </inertial>
    <visual>
      <origin
        xyz="0 0 0"
        rpy="0 0 0" />
      <geometry>
        <mesh
          filename="package://Assem1.SLDASM/meshes/Right Wheel.STL" />
      </geometry>
      <material
        name="">
        <color
          rgba="0.79216 0.81961 0.93333 1" />
      </material>
    </visual>
    <collision>
      <origin
        xyz="0 0 0"
        rpy="0 0 0" />
      <geometry>
        <mesh
          filename="package://Assem1.SLDASM/meshes/Right Wheel.STL" />
      </geometry>
    </collision>
  </link>
  <joint
    name="Right Wheel motor"
    type="continuous">
    <origin
      xyz="0.066969 0.049799 0.20951"
      rpy="2.8701 0 0" />
    <parent
      link="base_link" />
    <child
      link="Right Wheel" />
    <axis
      xyz="1 0 0" />
  </joint>
  <link
    name="Left wheel">
    <inertial>
      <origin
        xyz="0.017364 0 0"
        rpy="0 0 0" />
      <mass
        value="0.087" />
      <inertia
        ixx="2.1887E-05"
        ixy="9.9881E-21"
        ixz="1.1781E-21"
        iyy="1.1643E-05"
        iyz="-3.8798E-22"
        izz="1.1643E-05" />
    </inertial>
    <visual>
      <origin
        xyz="0 0 0"
        rpy="0 0 0" />
      <geometry>
        <mesh
          filename="package://Assem1.SLDASM/meshes/Left wheel.STL" />
      </geometry>
      <material
        name="">
        <color
          rgba="0.79216 0.81961 0.93333 1" />
      </material>
    </visual>
    <collision>
      <origin
        xyz="0 0 0"
        rpy="0 0 0" />
      <geometry>
        <mesh
          filename="package://Assem1.SLDASM/meshes/Left wheel.STL" />
      </geometry>
    </collision>
  </link>
  <joint
    name="left wheel motor"
    type="continuous">
    <origin
      xyz="0.23297 0.049799 0.20951"
      rpy="1.5708 0 0" />
    <parent
      link="base_link" />
    <child
      link="Left wheel" />
    <axis
      xyz="1 0 0" />
  </joint>
  <link
    name="Link1">
    <inertial>
      <origin
        xyz="0.022633 0.036293 -0.039596"
        rpy="0 0 0" />
      <mass
        value="0.087" />
      <inertia
        ixx="1.4841E-05"
        ixy="-8.741E-08"
        ixz="1.0825E-07"
        iyy="1.3018E-05"
        iyz="5.4384E-06"
        izz="9.564E-06" />
    </inertial>
    <visual>
      <origin
        xyz="0 0 0"
        rpy="0 0 0" />
      <geometry>
        <mesh
          filename="package://Assem1.SLDASM/meshes/Link1.STL" />
      </geometry>
      <material
        name="">
        <color
          rgba="0.79216 0.81961 0.93333 1" />
      </material>
    </visual>
    <collision>
      <origin
        xyz="0 0 0"
        rpy="0 0 0" />
      <geometry>
        <mesh
          filename="package://Assem1.SLDASM/meshes/Link1.STL" />
      </geometry>
    </collision>
  </link>
  <joint
    name="Movable link1"
    type="revolute">
    <origin
      xyz="0.13447 0.18641 0.24486"
      rpy="1.2932 0 0" />
    <parent
      link="base_link" />
    <child
      link="Link1" />
    <axis
      xyz="1 0 0" />
    <limit effort="100" lower="1.57" upper="-1.2" velocity="100"/>

  </joint>
  <link
    name="Link2">
    <inertial>
      <origin
        xyz="0.002 -0.016351 -0.012166"
        rpy="0 0 0" />
      <mass
        value="0.0059381" />
      <inertia
        ixx="2.9344E-06"
        ixy="-5.2841E-23"
        ixz="-4.6606E-23"
        iyy="1.1103E-06"
        iyz="-1.1561E-06"
        izz="1.8399E-06" />
    </inertial>
    <visual>
      <origin
        xyz="0 0 0"
        rpy="0 0 0" />
      <geometry>
        <mesh
          filename="package://Assem1.SLDASM/meshes/Link2.STL" />
      </geometry>
      <material
        name="">
        <color
          rgba="0.79216 0.81961 0.93333 1" />
      </material>
    </visual>
    <collision>
      <origin
        xyz="0 0 0"
        rpy="0 0 0" />
      <geometry>
        <mesh
          filename="package://Assem1.SLDASM/meshes/Link2.STL" />
      </geometry>
    </collision>
  </link>
  <joint
    name="Movable link2"
    type="revolute">
    <origin
      xyz="0.047 0.048315 -0.05205"
      rpy="0.66128 0 0" />
    <parent
      link="Link1" />
    <child
      link="Link2" />
    <axis
      xyz="1 0 0" />
    <limit effort="100" lower="1.57" upper="-1.2" velocity="100"/>

  </joint>
</robot>